Workbook
Name flt_analyst: 'KPI Dashboard'!$Q$3
Name flt_month: 'KPI Dashboard'!$J$3
Name flt_queue: 'KPI Dashboard'!$M$3

Sheet KPI Dashboard
F3: =MAX(tbl_raw_data[updated_date]) -> 45168 | G3: ="Last Update: "&TEXT(F3,"mmm-dd") -> Last Update: Aug-30 | I3: Month: | J3: AUGUST | L3: Queue Name: | M3: ALL | P3: Analyst Name: | Q3: ALL
S5: Reasons | T5: # of apps | U5: % Contribution | V5: Last 30 days Tarends
S6: Incorrect Details | T6: =IF(AND(flt_queue="ALL",flt_analyst="ALL"),COUNTIFS(tbl_raw_data[updated_month],flt_month,tbl_raw_data[updated_message],S6), IF(AND(flt_queue<>"ALL",flt_analyst<>"ALL"),COUNTIFS(tbl_raw_data[updated_month],flt_month,tbl_raw_data[updated_queue],flt_queue,tbl_raw_data[analyst_name],flt_analyst,tbl_raw_data[updated_message],S6), IF(flt_queue="ALL",COUNTIFS(tbl_raw_data[updated_month],flt_month,tbl_raw_data[analyst_name],flt_analyst,tbl_raw_data[updated_message],S6), IF(flt_analyst="ALL",COUNTIFS(tbl_raw_data[updated_month],flt_month,tbl_raw_data[updated_queue],flt_queue,tbl_raw_data[updated_message],S6))))) -> 127 | U6: =T6/T13 -> 0.079275905
B7: KPI # | C7: KPI Name | D7: Current Vs Pervious | E7: week 4 | F7: week 3 | G7: week 2 | H7: week 1 | I7: See Notes | J7: Trend | K7: ="Month: "&flt_month& "; Queue: "&flt_queue& "; Analyst: "&flt_analyst -> Month: AUGUST; Queue: ALL; Analyst: ALL | S7: Overdue Bill | T7: =IF(AND(flt_queue="ALL",flt_analyst="ALL"),COUNTIFS(tbl_raw_data[updated_month],flt_month,tbl_raw_data[updated_message],S7,tbl_raw_data[updated_outcome],"WITHDRAW"), IF(AND(flt_queue<>"ALL",flt_analyst<>"ALL"),COUNTIFS(tbl_raw_data[updated_month],flt_month,tbl_raw_data[updated_queue],flt_queue,tbl_raw_data[analyst_name],flt_analyst,tbl_raw_data[updated_message],S7,tbl_raw_data[updated_outcome],"WITHDRAW"), IF(flt_queue="ALL",COUNTIFS(tbl_raw_data[updated_month],flt_month,tbl_raw_data[analyst_name],flt_analyst,tbl_raw_data[updated_message],S7,tbl_raw_data[updated_outcome],"WITHDRAW"), IF(flt_analyst="ALL",COUNTIFS(tbl_raw_data[updated_month],flt_month,tbl_raw_data[updated_queue],flt_queue,tbl_raw_data[updated_message],S7,tbl_raw_data[updated_outcome],"WITHDRAW"))))) -> 156 | U7: =T7/$T$13 -> 0.097378277
B8: KPI_1 | C8: % of Applications Approved | D8: =IF(OR(E8="-",F8="-"),"-",IF(E8>F8,settings!J3,IF(E8<F8,settings!J2,IF(E8=F8,#REF!)))) -> ↑ | E8: =IFERROR(IF(AND(flt_queue="ALL",flt_analyst="ALL"),COUNTIFS(tbl_raw_data[updated_month],flt_month,tbl_raw_data[updated_outcome],"APPROVE",tbl_raw_data[week],E7), IF(AND(flt_queue<>"ALL",flt_analyst<>"ALL"),COUNTIFS(tbl_raw_data[updated_month],flt_month,tbl_raw_data[updated_queue],flt_queue,tbl_raw_data[analyst_name],flt_analyst,tbl_raw_data[updated_outcome],"APPROVE",tbl_raw_data[week],E7), IF(flt_queue="ALL",COUNTIFS(tbl_raw_data[updated_month],flt_month,tbl_raw_data[analyst_name],flt_analyst,tbl_raw_data[updated_outcome],"APPROVE",tbl_raw_data[week],E7), IF(flt_analyst="ALL",COUNTIFS(tbl_raw_data[updated_month],flt_month,tbl_raw_data[updated_queue],flt_queue,tbl_raw_data[updated_outcome],"APPROVE",tbl_raw_data[week],E7))))) / IF(AND(flt_queue="ALL",flt_analyst="ALL"),COUNTIFS(tbl_raw_data[updated_month],flt_month,tbl_raw_data[week],E7), IF(AND(flt_queue<>"ALL",flt_analyst<>"ALL"),COUNTIFS(tbl_raw_data[updated_month],flt_month,tbl_raw_data[updated_queue],flt_queue,tbl_raw_data[analyst_name],flt_analyst,tbl_raw_data[week],E7), IF(flt_queue="ALL",COUNTIFS(tbl_raw_data[updated_month],flt_month,tbl_raw_data[analyst_name],flt_analyst,tbl_raw_data[week],E7), IF(flt_analyst="ALL",COUNTIFS(tbl_raw_data[updated_month],flt_month,tbl_raw_data[updated_queue],flt_queue,tbl_raw_data[week],E7))))),"-") -> 0.57015458 | F8: =IFERROR(IF(AND(flt_queue="ALL",flt_analyst="ALL"),COUNTIFS(tbl_raw_data[updated_month],flt_month,tbl_raw_data[updated_outcome],"APPROVE",tbl_raw_data[week],F7), IF(AND(flt_queue<>"ALL",flt_analyst<>"ALL"),COUNTIFS(tbl_raw_data[updated_month],flt_month,tbl_raw_data[updated_queue],flt_queue,tbl_raw_data[analyst_name],flt_analyst,tbl_raw_data[updated_outcome],"APPROVE",tbl_raw_data[week],F7), IF(flt_queue="ALL",COUNTIFS(tbl_raw_data[updated_month],flt_month,tbl_raw_data[analyst_name],flt_analyst,tbl_raw_data[updated_outcome],"APPROVE",tbl_raw_data[week],F7), IF(flt_analyst="ALL",COUNTIFS(tbl_raw_data[updated_month],flt_month,tbl_raw_data[updated_queue],flt_queue,tbl_raw_data[updated_outcome],"APPROVE",tbl_raw_data[week],F7))))) / IF(AND(flt_queue="ALL",flt_analyst="ALL"),COUNTIFS(tbl_raw_data[updated_month],flt_month,tbl_raw_data[week],F7), IF(AND(flt_queue<>"ALL",flt_analyst<>"ALL"),COUNTIFS(tbl_raw_data[updated_month],flt_month,tbl_raw_data[updated_queue],flt_queue,tbl_raw_data[analyst_name],flt_analyst,tbl_raw_data[week],F7), IF(flt_queue="ALL",COUNTIFS(tbl_raw_data[updated_month],flt_month,tbl_raw_data[analyst_name],flt_analyst,tbl_raw_data[week],F7), IF(flt_analyst="ALL",COUNTIFS(tbl_raw_data[updated_month],flt_month,tbl_raw_data[updated_queue],flt_queue,tbl_raw_data[week],F7))))),"-") -> 0.53585197 | G8: =IFERROR(IF(AND(flt_queue="ALL",flt_analyst="ALL"),COUNTIFS(tbl_raw_data[updated_month],flt_month,tbl_raw_data[updated_outcome],"APPROVE",tbl_raw_data[week],G7), IF(AND(flt_queue<>"ALL",flt_analyst<>"ALL"),COUNTIFS(tbl_raw_data[updated_month],flt_month,tbl_raw_data[updated_queue],flt_queue,tbl_raw_data[analyst_name],flt_analyst,tbl_raw_data[updated_outcome],"APPROVE",tbl_raw_data[week],G7), IF(flt_queue="ALL",COUNTIFS(tbl_raw_data[updated_month],flt_month,tbl_raw_data[analyst_name],flt_analyst,tbl_raw_data[updated_outcome],"APPROVE",tbl_raw_data[week],G7), IF(flt_analyst="ALL",COUNTIFS(tbl_raw_data[updated_month],flt_month,tbl_raw_data[updated_queue],flt_queue,tbl_raw_data[updated_outcome],"APPROVE",tbl_raw_data[week],G7))))) / IF(AND(flt_queue="ALL",flt_analyst="ALL"),COUNTIFS(tbl_raw_data[updated_month],flt_month,tbl_raw_data[week],G7), IF(AND(flt_queue<>"ALL",flt_analyst<>"ALL"),COUNTIFS(tbl_raw_data[updated_month],flt_month,tbl_raw_data[updated_queue],flt_queue,tbl_raw_data[analyst_name],flt_analyst,tbl_raw_data[week],G7), IF(flt_queue="ALL",COUNTIFS(tbl_raw_data[updated_month],flt_month,tbl_raw_data[analyst_name],flt_analyst,tbl_raw_data[week],G7), IF(flt_analyst="ALL",COUNTIFS(tbl_raw_data[updated_month],flt_month,tbl_raw_data[updated_queue],flt_queue,tbl_raw_data[week],G7))))),"-") -> 0.54039216 | H8: =IFERROR(IF(AND(flt_queue="ALL",flt_analyst="ALL"),COUNTIFS(tbl_raw_data[updated_month],flt_month,tbl_raw_data[updated_outcome],"APPROVE",tbl_raw_data[week],H7), IF(AND(flt_queue<>"ALL",flt_analyst<>"ALL"),COUNTIFS(tbl_raw_data[updated_month],flt_month,tbl_raw_data[updated_queue],flt_queue,tbl_raw_data[analyst_name],flt_analyst,tbl_raw_data[updated_outcome],"APPROVE",tbl_raw_data[week],H7), IF(flt_queue="ALL",COUNTIFS(tbl_raw_data[updated_month],flt_month,tbl_raw_data[analyst_name],flt_analyst,tbl_raw_data[updated_outcome],"APPROVE",tbl_raw_data[week],H7), IF(flt_analyst="ALL",COUNTIFS(tbl_raw_data[updated_month],flt_month,tbl_raw_data[updated_queue],flt_queue,tbl_raw_data[updated_outcome],"APPROVE",tbl_raw_data[week],H7))))) / IF(AND(flt_queue="ALL",flt_analyst="ALL"),COUNTIFS(tbl_raw_data[updated_month],flt_month,tbl_raw_data[week],H7), IF(AND(flt_queue<>"ALL",flt_analyst<>"ALL"),COUNTIFS(tbl_raw_data[updated_month],flt_month,tbl_raw_data[updated_queue],flt_queue,tbl_raw_data[analyst_name],flt_analyst,tbl_raw_data[week],H7), IF(flt_queue="ALL",COUNTIFS(tbl_raw_data[updated_month],flt_month,tbl_raw_data[analyst_name],flt_analyst,tbl_raw_data[week],H7), IF(flt_analyst="ALL",COUNTIFS(tbl_raw_data[updated_month],flt_month,tbl_raw_data[updated_queue],flt_queue,tbl_raw_data[week],H7))))),"-") -> 0.59728507 | I8: R: <75% A: 75%-85% G: >85% | K8: =IF(AND(flt_queue="ALL",flt_analyst="ALL"),COUNTIFS(tbl_raw_data[updated_month],flt_month,tbl_raw_data[updated_outcome],"APPROVE"), IF(AND(flt_queue<>"ALL",flt_analyst<>"ALL"),COUNTIFS(tbl_raw_data[updated_month],flt_month,tbl_raw_data[updated_queue],flt_queue,tbl_raw_data[analyst_name],flt_analyst,tbl_raw_data[updated_outcome],"APPROVE"), IF(flt_queue="ALL",COUNTIFS(tbl_raw_data[updated_month],flt_month,tbl_raw_data[analyst_name],flt_analyst,tbl_raw_data[updated_outcome],"APPROVE"), IF(flt_analyst="ALL",COUNTIFS(tbl_raw_data[updated_month],flt_month,tbl_raw_data[updated_queue],flt_queue,tbl_raw_data[updated_outcome],"APPROVE"))))) / IF(AND(flt_queue="ALL",flt_analyst="ALL"),COUNTIFS(tbl_raw_data[updated_month],flt_month), IF(AND(flt_queue<>"ALL",flt_analyst<>"ALL"),COUNTIFS(tbl_raw_data[updated_month],flt_month,tbl_raw_data[updated_queue],flt_queue,tbl_raw_data[analyst_name],flt_analyst), IF(flt_queue="ALL",COUNTIFS(tbl_raw_data[updated_month],flt_month,tbl_raw_data[analyst_name],flt_analyst), IF(flt_analyst="ALL",COUNTIFS(tbl_raw_data[updated_month],flt_month,tbl_raw_data[updated_queue],flt_queue))))) -> 0.56182796 | S8: Incomplete Details | T8: =IF(AND(flt_queue="ALL",flt_analyst="ALL"),COUNTIFS(tbl_raw_data[updated_month],flt_month,tbl_raw_data[updated_message],S8,tbl_raw_data[updated_outcome],"WITHDRAW"), IF(AND(flt_queue<>"ALL",flt_analyst<>"ALL"),COUNTIFS(tbl_raw_data[updated_month],flt_month,tbl_raw_data[updated_queue],flt_queue,tbl_raw_data[analyst_name],flt_analyst,tbl_raw_data[updated_message],S8,tbl_raw_data[updated_outcome],"WITHDRAW"), IF(flt_queue="ALL",COUNTIFS(tbl_raw_data[updated_month],flt_month,tbl_raw_data[analyst_name],flt_analyst,tbl_raw_data[updated_message],S8,tbl_raw_data[updated_outcome],"WITHDRAW"), IF(flt_analyst="ALL",COUNTIFS(tbl_raw_data[updated_month],flt_month,tbl_raw_data[updated_queue],flt_queue,tbl_raw_data[updated_message],S8,tbl_raw_data[updated_outcome],"WITHDRAW"))))) -> 841 | U8: =T8/$T$13 -> 0.52496879
B9: KPI_2 | C9: % of Applications Declined | D9: =IF(OR(E9="-",F9="-"),"-",IF(E9<F9,settings!J3,IF(E9>F9,settings!J2,IF(E9=F9,#REF!)))) -> ↑ | E9: =IFERROR(IF(AND(flt_queue="ALL",flt_analyst="ALL"),COUNTIFS(tbl_raw_data[updated_month],flt_month,tbl_raw_data[updated_outcome],"DECLINE",tbl_raw_data[week],E7), IF(AND(flt_queue<>"ALL",flt_analyst<>"ALL"),COUNTIFS(tbl_raw_data[updated_month],flt_month,tbl_raw_data[updated_queue],flt_queue,tbl_raw_data[analyst_name],flt_analyst,tbl_raw_data[updated_outcome],"DECLINE",tbl_raw_data[week],E7), IF(flt_queue="ALL",COUNTIFS(tbl_raw_data[updated_month],flt_month,tbl_raw_data[analyst_name],flt_analyst,tbl_raw_data[updated_outcome],"DECLINE",tbl_raw_data[week],E7), IF(flt_analyst="ALL",COUNTIFS(tbl_raw_data[updated_month],flt_month,tbl_raw_data[updated_queue],flt_queue,tbl_raw_data[updated_outcome],"DECLINE",tbl_raw_data[week],E7))))) / IF(AND(flt_queue="ALL",flt_analyst="ALL"),COUNTIFS(tbl_raw_data[updated_month],flt_month,tbl_raw_data[week],E7), IF(AND(flt_queue<>"ALL",flt_analyst<>"ALL"),COUNTIFS(tbl_raw_data[updated_month],flt_month,tbl_raw_data[updated_queue],flt_queue,tbl_raw_data[analyst_name],flt_analyst,tbl_raw_data[week],E7), IF(flt_queue="ALL",COUNTIFS(tbl_raw_data[updated_month],flt_month,tbl_raw_data[analyst_name],flt_analyst,tbl_raw_data[week],E7), IF(flt_analyst="ALL",COUNTIFS(tbl_raw_data[updated_month],flt_month,tbl_raw_data[updated_queue],flt_queue,tbl_raw_data[week],E7))))),"-") -> 0.13317479 | F9: =IFERROR(IF(AND(flt_queue="ALL",flt_analyst="ALL"),COUNTIFS(tbl_raw_data[updated_month],flt_month,tbl_raw_data[updated_outcome],"DECLINE",tbl_raw_data[week],F7), IF(AND(flt_queue<>"ALL",flt_analyst<>"ALL"),COUNTIFS(tbl_raw_data[updated_month],flt_month,tbl_raw_data[updated_queue],flt_queue,tbl_raw_data[analyst_name],flt_analyst,tbl_raw_data[updated_outcome],"DECLINE",tbl_raw_data[week],F7), IF(flt_queue="ALL",COUNTIFS(tbl_raw_data[updated_month],flt_month,tbl_raw_data[analyst_name],flt_analyst,tbl_raw_data[updated_outcome],"DECLINE",tbl_raw_data[week],F7), IF(flt_analyst="ALL",COUNTIFS(tbl_raw_data[updated_month],flt_month,tbl_raw_data[updated_queue],flt_queue,tbl_raw_data[updated_outcome],"DECLINE",tbl_raw_data[week],F7))))) / IF(AND(flt_queue="ALL",flt_analyst="ALL"),COUNTIFS(tbl_raw_data[updated_month],flt_month,tbl_raw_data[week],F7), IF(AND(flt_queue<>"ALL",flt_analyst<>"ALL"),COUNTIFS(tbl_raw_data[updated_month],flt_month,tbl_raw_data[updated_queue],flt_queue,tbl_raw_data[analyst_name],flt_analyst,tbl_raw_data[week],F7), IF(flt_queue="ALL",COUNTIFS(tbl_raw_data[updated_month],flt_month,tbl_raw_data[analyst_name],flt_analyst,tbl_raw_data[week],F7), IF(flt_analyst="ALL",COUNTIFS(tbl_raw_data[updated_month],flt_month,tbl_raw_data[updated_queue],flt_queue,tbl_raw_data[week],F7))))),"-") -> 0.15343099 | G9: =IFERROR(IF(AND(flt_queue="ALL",flt_analyst="ALL"),COUNTIFS(tbl_raw_data[updated_month],flt_month,tbl_raw_data[updated_outcome],"DECLINE",tbl_raw_data[week],G7), IF(AND(flt_queue<>"ALL",flt_analyst<>"ALL"),COUNTIFS(tbl_raw_data[updated_month],flt_month,tbl_raw_data[updated_queue],flt_queue,tbl_raw_data[analyst_name],flt_analyst,tbl_raw_data[updated_outcome],"DECLINE",tbl_raw_data[week],G7), IF(flt_queue="ALL",COUNTIFS(tbl_raw_data[updated_month],flt_month,tbl_raw_data[analyst_name],flt_analyst,tbl_raw_data[updated_outcome],"DECLINE",tbl_raw_data[week],G7), IF(flt_analyst="ALL",COUNTIFS(tbl_raw_data[updated_month],flt_month,tbl_raw_data[updated_queue],flt_queue,tbl_raw_data[updated_outcome],"DECLINE",tbl_raw_data[week],G7))))) / IF(AND(flt_queue="ALL",flt_analyst="ALL"),COUNTIFS(tbl_raw_data[updated_month],flt_month,tbl_raw_data[week],G7), IF(AND(flt_queue<>"ALL",flt_analyst<>"ALL"),COUNTIFS(tbl_raw_data[updated_month],flt_month,tbl_raw_data[updated_queue],flt_queue,tbl_raw_data[analyst_name],flt_analyst,tbl_raw_data[week],G7), IF(flt_queue="ALL",COUNTIFS(tbl_raw_data[updated_month],flt_month,tbl_raw_data[analyst_name],flt_analyst,tbl_raw_data[week],G7), IF(flt_analyst="ALL",COUNTIFS(tbl_raw_data[updated_month],flt_month,tbl_raw_data[updated_queue],flt_queue,tbl_raw_data[week],G7))))),"-") -> 0.12 | H9: =IFERROR(IF(AND(flt_queue="ALL",flt_analyst="ALL"),COUNTIFS(tbl_raw_data[updated_month],flt_month,tbl_raw_data[updated_outcome],"DECLINE",tbl_raw_data[week],H7), IF(AND(flt_queue<>"ALL",flt_analyst<>"ALL"),COUNTIFS(tbl_raw_data[updated_month],flt_month,tbl_raw_data[updated_queue],flt_queue,tbl_raw_data[analyst_name],flt_analyst,tbl_raw_data[updated_outcome],"DECLINE",tbl_raw_data[week],H7), IF(flt_queue="ALL",COUNTIFS(tbl_raw_data[updated_month],flt_month,tbl_raw_data[analyst_name],flt_analyst,tbl_raw_data[updated_outcome],"DECLINE",tbl_raw_data[week],H7), IF(flt_analyst="ALL",COUNTIFS(tbl_raw_data[updated_month],flt_month,tbl_raw_data[updated_queue],flt_queue,tbl_raw_data[updated_outcome],"DECLINE",tbl_raw_data[week],H7))))) / IF(AND(flt_queue="ALL",flt_analyst="ALL"),COUNTIFS(tbl_raw_data[updated_month],flt_month,tbl_raw_data[week],H7), IF(AND(flt_queue<>"ALL",flt_analyst<>"ALL"),COUNTIFS(tbl_raw_data[updated_month],flt_month,tbl_raw_data[updated_queue],flt_queue,tbl_raw_data[analyst_name],flt_analyst,tbl_raw_data[week],H7), IF(flt_queue="ALL",COUNTIFS(tbl_raw_data[updated_month],flt_month,tbl_raw_data[analyst_name],flt_analyst,tbl_raw_data[week],H7), IF(flt_analyst="ALL",COUNTIFS(tbl_raw_data[updated_month],flt_month,tbl_raw_data[updated_queue],flt_queue,tbl_raw_data[week],H7))))),"-") -> 0.10708899 | I9: R: >20% A: 10%-20% G: <10% | K9: =IF(AND(flt_queue="ALL",flt_analyst="ALL"),COUNTIFS(tbl_raw_data[updated_month],flt_month,tbl_raw_data[updated_outcome],"DECLINE"), IF(AND(flt_queue<>"ALL",flt_analyst<>"ALL"),COUNTIFS(tbl_raw_data[updated_month],flt_month,tbl_raw_data[updated_queue],flt_queue,tbl_raw_data[analyst_name],flt_analyst,tbl_raw_data[updated_outcome],"DECLINE"), IF(flt_queue="ALL",COUNTIFS(tbl_raw_data[updated_month],flt_month,tbl_raw_data[analyst_name],flt_analyst,tbl_raw_data[updated_outcome],"DECLINE"), IF(flt_analyst="ALL",COUNTIFS(tbl_raw_data[updated_month],flt_month,tbl_raw_data[updated_queue],flt_queue,tbl_raw_data[updated_outcome],"DECLINE"))))) / IF(AND(flt_queue="ALL",flt_analyst="ALL"),COUNTIFS(tbl_raw_data[updated_month],flt_month), IF(AND(flt_queue<>"ALL",flt_analyst<>"ALL"),COUNTIFS(tbl_raw_data[updated_month],flt_month,tbl_raw_data[updated_queue],flt_queue,tbl_raw_data[analyst_name],flt_analyst), IF(flt_queue="ALL",COUNTIFS(tbl_raw_data[updated_month],flt_month,tbl_raw_data[analyst_name],flt_analyst), IF(flt_analyst="ALL",COUNTIFS(tbl_raw_data[updated_month],flt_month,tbl_raw_data[updated_queue],flt_queue))))) -> 0.12867384 | S9: Incorrect Queue | T9: =IF(AND(flt_queue="ALL",flt_analyst="ALL"),COUNTIFS(tbl_raw_data[updated_month],flt_month,tbl_raw_data[updated_message],S9,tbl_raw_data[updated_outcome],"WITHDRAW"), IF(AND(flt_queue<>"ALL",flt_analyst<>"ALL"),COUNTIFS(tbl_raw_data[updated_month],flt_month,tbl_raw_data[updated_queue],flt_queue,tbl_raw_data[analyst_name],flt_analyst,tbl_raw_data[updated_message],S9,tbl_raw_data[updated_outcome],"WITHDRAW"), IF(flt_queue="ALL",COUNTIFS(tbl_raw_data[updated_month],flt_month,tbl_raw_data[analyst_name],flt_analyst,tbl_raw_data[updated_message],S9,tbl_raw_data[updated_outcome],"WITHDRAW"), IF(flt_analyst="ALL",COUNTIFS(tbl_raw_data[updated_month],flt_month,tbl_raw_data[updated_queue],flt_queue,tbl_raw_data[updated_message],S9,tbl_raw_data[updated_outcome],"WITHDRAW"))))) -> 185 | U9: =T9/$T$13 -> 0.11548065 | Y9: \,
B10: KPI_3 | C10: % of Applications Withdrawn | D10: =IF(OR(E10="-",F10="-"),"-",IF(E10>F10,settings!J2,IF(E10<F10,settings!J3,IF(E10=F10,#REF!)))) -> ↑ | E10: =IFERROR(IF(AND(flt_queue="ALL",flt_analyst="ALL"),COUNTIFS(tbl_raw_data[updated_month],flt_month,tbl_raw_data[updated_outcome],"WITHDRAW",tbl_raw_data[week],E7), IF(AND(flt_queue<>"ALL",flt_analyst<>"ALL"),COUNTIFS(tbl_raw_data[updated_month],flt_month,tbl_raw_data[updated_queue],flt_queue,tbl_raw_data[analyst_name],flt_analyst,tbl_raw_data[updated_outcome],"WITHDRAW",tbl_raw_data[week],E7), IF(flt_queue="ALL",COUNTIFS(tbl_raw_data[updated_month],flt_month,tbl_raw_data[analyst_name],flt_analyst,tbl_raw_data[updated_outcome],"WITHDRAW",tbl_raw_data[week],E7), IF(flt_analyst="ALL",COUNTIFS(tbl_raw_data[updated_month],flt_month,tbl_raw_data[updated_queue],flt_queue,tbl_raw_data[updated_outcome],"WITHDRAW",tbl_raw_data[week],E7))))) / IF(AND(flt_queue="ALL",flt_analyst="ALL"),COUNTIFS(tbl_raw_data[updated_month],flt_month,tbl_raw_data[week],E7), IF(AND(flt_queue<>"ALL",flt_analyst<>"ALL"),COUNTIFS(tbl_raw_data[updated_month],flt_month,tbl_raw_data[updated_queue],flt_queue,tbl_raw_data[analyst_name],flt_analyst,tbl_raw_data[week],E7), IF(flt_queue="ALL",COUNTIFS(tbl_raw_data[updated_month],flt_month,tbl_raw_data[analyst_name],flt_analyst,tbl_raw_data[week],E7), IF(flt_analyst="ALL",COUNTIFS(tbl_raw_data[updated_month],flt_month,tbl_raw_data[updated_queue],flt_queue,tbl_raw_data[week],E7))))),"-") -> 0.29667063 | F10: =IFERROR(IF(AND(flt_queue="ALL",flt_analyst="ALL"),COUNTIFS(tbl_raw_data[updated_month],flt_month,tbl_raw_data[updated_outcome],"WITHDRAW",tbl_raw_data[week],F7), IF(AND(flt_queue<>"ALL",flt_analyst<>"ALL"),COUNTIFS(tbl_raw_data[updated_month],flt_month,tbl_raw_data[updated_queue],flt_queue,tbl_raw_data[analyst_name],flt_analyst,tbl_raw_data[updated_outcome],"WITHDRAW",tbl_raw_data[week],F7), IF(flt_queue="ALL",COUNTIFS(tbl_raw_data[updated_month],flt_month,tbl_raw_data[analyst_name],flt_analyst,tbl_raw_data[updated_outcome],"WITHDRAW",tbl_raw_data[week],F7), IF(flt_analyst="ALL",COUNTIFS(tbl_raw_data[updated_month],flt_month,tbl_raw_data[updated_queue],flt_queue,tbl_raw_data[updated_outcome],"WITHDRAW",tbl_raw_data[week],F7))))) / IF(AND(flt_queue="ALL",flt_analyst="ALL"),COUNTIFS(tbl_raw_data[updated_month],flt_month,tbl_raw_data[week],F7), IF(AND(flt_queue<>"ALL",flt_analyst<>"ALL"),COUNTIFS(tbl_raw_data[updated_month],flt_month,tbl_raw_data[updated_queue],flt_queue,tbl_raw_data[analyst_name],flt_analyst,tbl_raw_data[week],F7), IF(flt_queue="ALL",COUNTIFS(tbl_raw_data[updated_month],flt_month,tbl_raw_data[analyst_name],flt_analyst,tbl_raw_data[week],F7), IF(flt_analyst="ALL",COUNTIFS(tbl_raw_data[updated_month],flt_month,tbl_raw_data[updated_queue],flt_queue,tbl_raw_data[week],F7))))),"-") -> 0.31071704 | G10: =IFERROR(IF(AND(flt_queue="ALL",flt_analyst="ALL"),COUNTIFS(tbl_raw_data[updated_month],flt_month,tbl_raw_data[updated_outcome],"WITHDRAW",tbl_raw_data[week],G7), IF(AND(flt_queue<>"ALL",flt_analyst<>"ALL"),COUNTIFS(tbl_raw_data[updated_month],flt_month,tbl_raw_data[updated_queue],flt_queue,tbl_raw_data[analyst_name],flt_analyst,tbl_raw_data[updated_outcome],"WITHDRAW",tbl_raw_data[week],G7), IF(flt_queue="ALL",COUNTIFS(tbl_raw_data[updated_month],flt_month,tbl_raw_data[analyst_name],flt_analyst,tbl_raw_data[updated_outcome],"WITHDRAW",tbl_raw_data[week],G7), IF(flt_analyst="ALL",COUNTIFS(tbl_raw_data[updated_month],flt_month,tbl_raw_data[updated_queue],flt_queue,tbl_raw_data[updated_outcome],"WITHDRAW",tbl_raw_data[week],G7))))) / IF(AND(flt_queue="ALL",flt_analyst="ALL"),COUNTIFS(tbl_raw_data[updated_month],flt_month,tbl_raw_data[week],G7), IF(AND(flt_queue<>"ALL",flt_analyst<>"ALL"),COUNTIFS(tbl_raw_data[updated_month],flt_month,tbl_raw_data[updated_queue],flt_queue,tbl_raw_data[analyst_name],flt_analyst,tbl_raw_data[week],G7), IF(flt_queue="ALL",COUNTIFS(tbl_raw_data[updated_month],flt_month,tbl_raw_data[analyst_name],flt_analyst,tbl_raw_data[week],G7), IF(flt_analyst="ALL",COUNTIFS(tbl_raw_data[updated_month],flt_month,tbl_raw_data[updated_queue],flt_queue,tbl_raw_data[week],G7))))),"-") -> 0.33960784 | H10: =IFERROR(IF(AND(flt_queue="ALL",flt_analyst="ALL"),COUNTIFS(tbl_raw_data[updated_month],flt_month,tbl_raw_data[updated_outcome],"WITHDRAW",tbl_raw_data[week],H7), IF(AND(flt_queue<>"ALL",flt_analyst<>"ALL"),COUNTIFS(tbl_raw_data[updated_month],flt_month,tbl_raw_data[updated_queue],flt_queue,tbl_raw_data[analyst_name],flt_analyst,tbl_raw_data[updated_outcome],"WITHDRAW",tbl_raw_data[week],H7), IF(flt_queue="ALL",COUNTIFS(tbl_raw_data[updated_month],flt_month,tbl_raw_data[analyst_name],flt_analyst,tbl_raw_data[updated_outcome],"WITHDRAW",tbl_raw_data[week],H7), IF(flt_analyst="ALL",COUNTIFS(tbl_raw_data[updated_month],flt_month,tbl_raw_data[updated_queue],flt_queue,tbl_raw_data[updated_outcome],"WITHDRAW",tbl_raw_data[week],H7))))) / IF(AND(flt_queue="ALL",flt_analyst="ALL"),COUNTIFS(tbl_raw_data[updated_month],flt_month,tbl_raw_data[week],H7), IF(AND(flt_queue<>"ALL",flt_analyst<>"ALL"),COUNTIFS(tbl_raw_data[updated_month],flt_month,tbl_raw_data[updated_queue],flt_queue,tbl_raw_data[analyst_name],flt_analyst,tbl_raw_data[week],H7), IF(flt_queue="ALL",COUNTIFS(tbl_raw_data[updated_month],flt_month,tbl_raw_data[analyst_name],flt_analyst,tbl_raw_data[week],H7), IF(flt_analyst="ALL",COUNTIFS(tbl_raw_data[updated_month],flt_month,tbl_raw_data[updated_queue],flt_queue,tbl_raw_data[week],H7))))),"-") -> 0.29562594 | I10: R: >20% A: 10%-20% G: <10% | K10: =IF(AND(flt_queue="ALL",flt_analyst="ALL"),COUNTIFS(tbl_raw_data[updated_month],flt_month,tbl_raw_data[updated_outcome],"WITHDRAW"), IF(AND(flt_queue<>"ALL",flt_analyst<>"ALL"),COUNTIFS(tbl_raw_data[updated_month],flt_month,tbl_raw_data[updated_queue],flt_queue,tbl_raw_data[analyst_name],flt_analyst,tbl_raw_data[updated_outcome],"WITHDRAW"), IF(flt_queue="ALL",COUNTIFS(tbl_raw_data[updated_month],flt_month,tbl_raw_data[analyst_name],flt_analyst,tbl_raw_data[updated_outcome],"WITHDRAW"), IF(flt_analyst="ALL",COUNTIFS(tbl_raw_data[updated_month],flt_month,tbl_raw_data[updated_queue],flt_queue,tbl_raw_data[updated_outcome],"WITHDRAW"))))) / IF(AND(flt_queue="ALL",flt_analyst="ALL"),COUNTIFS(tbl_raw_data[updated_month],flt_month), IF(AND(flt_queue<>"ALL",flt_analyst<>"ALL"),COUNTIFS(tbl_raw_data[updated_month],flt_month,tbl_raw_data[updated_queue],flt_queue,tbl_raw_data[analyst_name],flt_analyst), IF(flt_queue="ALL",COUNTIFS(tbl_raw_data[updated_month],flt_month,tbl_raw_data[analyst_name],flt_analyst), IF(flt_analyst="ALL",COUNTIFS(tbl_raw_data[updated_month],flt_month,tbl_raw_data[updated_queue],flt_queue))))) -> 0.30949821 | S10: System Error | T10: =IF(AND(flt_queue="ALL",flt_analyst="ALL"),COUNTIFS(tbl_raw_data[updated_month],flt_month,tbl_raw_data[updated_message],S10,tbl_raw_data[updated_outcome],"WITHDRAW"), IF(AND(flt_queue<>"ALL",flt_analyst<>"ALL"),COUNTIFS(tbl_raw_data[updated_month],flt_month,tbl_raw_data[updated_queue],flt_queue,tbl_raw_data[analyst_name],flt_analyst,tbl_raw_data[updated_message],S10,tbl_raw_data[updated_outcome],"WITHDRAW"), IF(flt_queue="ALL",COUNTIFS(tbl_raw_data[updated_month],flt_month,tbl_raw_data[analyst_name],flt_analyst,tbl_raw_data[updated_message],S10,tbl_raw_data[updated_outcome],"WITHDRAW"), IF(flt_analyst="ALL",COUNTIFS(tbl_raw_data[updated_month],flt_month,tbl_raw_data[updated_queue],flt_queue,tbl_raw_data[updated_message],S10,tbl_raw_data[updated_outcome],"WITHDRAW"))))) -> 13 | U10: =T10/$T$13 -> 0.0081148564
B11: KPI_4 | C11: % of Applications within SLA (Service Level Agreement) | D11: =IF(OR(E11="-",F11="-"),"-",IF(E11>F11,settings!J3,IF(E11<F11,settings!J2,IF(E11=F11,#REF!)))) -> ↓ | E11: =IFERROR(IF(AND(flt_queue="ALL",flt_analyst="ALL"),COUNTIFS(tbl_raw_data[updated_month],flt_month,tbl_raw_data[sla_met_not_met],"SLA_MET",tbl_raw_data[week],E7), IF(AND(flt_queue<>"ALL",flt_analyst<>"ALL"),COUNTIFS(tbl_raw_data[updated_month],flt_month,tbl_raw_data[updated_queue],flt_queue,tbl_raw_data[analyst_name],flt_analyst,tbl_raw_data[sla_met_not_met],"SLA_MET",tbl_raw_data[week],E7), IF(flt_queue="ALL",COUNTIFS(tbl_raw_data[updated_month],flt_month,tbl_raw_data[analyst_name],flt_analyst,tbl_raw_data[sla_met_not_met],"SLA_MET",tbl_raw_data[week],E7), IF(flt_analyst="ALL",COUNTIFS(tbl_raw_data[updated_month],flt_month,tbl_raw_data[updated_queue],flt_queue,tbl_raw_data[sla_met_not_met],"SLA_MET",tbl_raw_data[week],E7))))) / IF(AND(flt_queue="ALL",flt_analyst="ALL"),COUNTIFS(tbl_raw_data[updated_month],flt_month,tbl_raw_data[week],E7), IF(AND(flt_queue<>"ALL",flt_analyst<>"ALL"),COUNTIFS(tbl_raw_data[updated_month],flt_month,tbl_raw_data[updated_queue],flt_queue,tbl_raw_data[analyst_name],flt_analyst,tbl_raw_data[week],E7), IF(flt_queue="ALL",COUNTIFS(tbl_raw_data[updated_month],flt_month,tbl_raw_data[analyst_name],flt_analyst,tbl_raw_data[week],E7), IF(flt_analyst="ALL",COUNTIFS(tbl_raw_data[updated_month],flt_month,tbl_raw_data[updated_queue],flt_queue,tbl_raw_data[week],E7))))),"-") -> 0.85315101 | F11: =IFERROR(IF(AND(flt_queue="ALL",flt_analyst="ALL"),COUNTIFS(tbl_raw_data[updated_month],flt_month,tbl_raw_data[sla_met_not_met],"SLA_MET",tbl_raw_data[week],F7), IF(AND(flt_queue<>"ALL",flt_analyst<>"ALL"),COUNTIFS(tbl_raw_data[updated_month],flt_month,tbl_raw_data[updated_queue],flt_queue,tbl_raw_data[analyst_name],flt_analyst,tbl_raw_data[sla_met_not_met],"SLA_MET",tbl_raw_data[week],F7), IF(flt_queue="ALL",COUNTIFS(tbl_raw_data[updated_month],flt_month,tbl_raw_data[analyst_name],flt_analyst,tbl_raw_data[sla_met_not_met],"SLA_MET",tbl_raw_data[week],F7), IF(flt_analyst="ALL",COUNTIFS(tbl_raw_data[updated_month],flt_month,tbl_raw_data[updated_queue],flt_queue,tbl_raw_data[sla_met_not_met],"SLA_MET",tbl_raw_data[week],F7))))) / IF(AND(flt_queue="ALL",flt_analyst="ALL"),COUNTIFS(tbl_raw_data[updated_month],flt_month,tbl_raw_data[week],F7), IF(AND(flt_queue<>"ALL",flt_analyst<>"ALL"),COUNTIFS(tbl_raw_data[updated_month],flt_month,tbl_raw_data[updated_queue],flt_queue,tbl_raw_data[analyst_name],flt_analyst,tbl_raw_data[week],F7), IF(flt_queue="ALL",COUNTIFS(tbl_raw_data[updated_month],flt_month,tbl_raw_data[analyst_name],flt_analyst,tbl_raw_data[week],F7), IF(flt_analyst="ALL",COUNTIFS(tbl_raw_data[updated_month],flt_month,tbl_raw_data[updated_queue],flt_queue,tbl_raw_data[week],F7))))),"-") -> 0.88511951 | G11: =IFERROR(IF(AND(flt_queue="ALL",flt_analyst="ALL"),COUNTIFS(tbl_raw_data[updated_month],flt_month,tbl_raw_data[sla_met_not_met],"SLA_MET",tbl_raw_data[week],G7), IF(AND(flt_queue<>"ALL",flt_analyst<>"ALL"),COUNTIFS(tbl_raw_data[updated_month],flt_month,tbl_raw_data[updated_queue],flt_queue,tbl_raw_data[analyst_name],flt_analyst,tbl_raw_data[sla_met_not_met],"SLA_MET",tbl_raw_data[week],G7), IF(flt_queue="ALL",COUNTIFS(tbl_raw_data[updated_month],flt_month,tbl_raw_data[analyst_name],flt_analyst,tbl_raw_data[sla_met_not_met],"SLA_MET",tbl_raw_data[week],G7), IF(flt_analyst="ALL",COUNTIFS(tbl_raw_data[updated_month],flt_month,tbl_raw_data[updated_queue],flt_queue,tbl_raw_data[sla_met_not_met],"SLA_MET",tbl_raw_data[week],G7))))) / IF(AND(flt_queue="ALL",flt_analyst="ALL"),COUNTIFS(tbl_raw_data[updated_month],flt_month,tbl_raw_data[week],G7), IF(AND(flt_queue<>"ALL",flt_analyst<>"ALL"),COUNTIFS(tbl_raw_data[updated_month],flt_month,tbl_raw_data[updated_queue],flt_queue,tbl_raw_data[analyst_name],flt_analyst,tbl_raw_data[week],G7), IF(flt_queue="ALL",COUNTIFS(tbl_raw_data[updated_month],flt_month,tbl_raw_data[analyst_name],flt_analyst,tbl_raw_data[week],G7), IF(flt_analyst="ALL",COUNTIFS(tbl_raw_data[updated_month],flt_month,tbl_raw_data[updated_queue],flt_queue,tbl_raw_data[week],G7))))),"-") -> 0.89803922 | H11: =IFERROR(IF(AND(flt_queue="ALL",flt_analyst="ALL"),COUNTIFS(tbl_raw_data[updated_month],flt_month,tbl_raw_data[sla_met_not_met],"SLA_MET",tbl_raw_data[week],H7), IF(AND(flt_queue<>"ALL",flt_analyst<>"ALL"),COUNTIFS(tbl_raw_data[updated_month],flt_month,tbl_raw_data[updated_queue],flt_queue,tbl_raw_data[analyst_name],flt_analyst,tbl_raw_data[sla_met_not_met],"SLA_MET",tbl_raw_data[week],H7), IF(flt_queue="ALL",COUNTIFS(tbl_raw_data[updated_month],flt_month,tbl_raw_data[analyst_name],flt_analyst,tbl_raw_data[sla_met_not_met],"SLA_MET",tbl_raw_data[week],H7), IF(flt_analyst="ALL",COUNTIFS(tbl_raw_data[updated_month],flt_month,tbl_raw_data[updated_queue],flt_queue,tbl_raw_data[sla_met_not_met],"SLA_MET",tbl_raw_data[week],H7))))) / IF(AND(flt_queue="ALL",flt_analyst="ALL"),COUNTIFS(tbl_raw_data[updated_month],flt_month,tbl_raw_data[week],H7), IF(AND(flt_queue<>"ALL",flt_analyst<>"ALL"),COUNTIFS(tbl_raw_data[updated_month],flt_month,tbl_raw_data[updated_queue],flt_queue,tbl_raw_data[analyst_name],flt_analyst,tbl_raw_data[week],H7), IF(flt_queue="ALL",COUNTIFS(tbl_raw_data[updated_month],flt_month,tbl_raw_data[analyst_name],flt_analyst,tbl_raw_data[week],H7), IF(flt_analyst="ALL",COUNTIFS(tbl_raw_data[updated_month],flt_month,tbl_raw_data[updated_queue],flt_queue,tbl_raw_data[week],H7))))),"-") -> 0.90422323 | I11: R: <80% A: 80%-90% G: >90% | S11: Duplicate Application | T11: =IF(AND(flt_queue="ALL",flt_analyst="ALL"),COUNTIFS(tbl_raw_data[updated_month],flt_month,tbl_raw_data[updated_message],S11,tbl_raw_data[updated_outcome],"WITHDRAW"), IF(AND(flt_queue<>"ALL",flt_analyst<>"ALL"),COUNTIFS(tbl_raw_data[updated_month],flt_month,tbl_raw_data[updated_queue],flt_queue,tbl_raw_data[analyst_name],flt_analyst,tbl_raw_data[updated_message],S11,tbl_raw_data[updated_outcome],"WITHDRAW"), IF(flt_queue="ALL",COUNTIFS(tbl_raw_data[updated_month],flt_month,tbl_raw_data[analyst_name],flt_analyst,tbl_raw_data[updated_message],S11,tbl_raw_data[updated_outcome],"WITHDRAW"), IF(flt_analyst="ALL",COUNTIFS(tbl_raw_data[updated_month],flt_month,tbl_raw_data[updated_queue],flt_queue,tbl_raw_data[updated_message],S11,tbl_raw_data[updated_outcome],"WITHDRAW"))))) -> 34 | U11: =T11/$T$13 -> 0.021223471
B12: KPI_5 | C12: Average handling Time(in min) | D12: =IF(OR(E12="-",F12="-"),"-",IF(E12>F12,settings!J2,IF(E12<F12,settings!J3,IF(E12=F12,settings!J4)))) -> ↑ | E12: =IFERROR(IF(AND(flt_queue="ALL",flt_analyst="ALL"),SUMIFS(tbl_raw_data[time_taken_in_min],tbl_raw_data[updated_month],flt_month,tbl_raw_data[week],E7), IF(AND(flt_queue<>"ALL",flt_analyst<>"ALL"),SUMIFS(tbl_raw_data[time_taken_in_min],tbl_raw_data[updated_month],flt_month,tbl_raw_data[updated_queue],flt_queue,tbl_raw_data[analyst_name],flt_analyst,tbl_raw_data[week],E7), IF(flt_queue="ALL",SUMIFS(tbl_raw_data[time_taken_in_min],tbl_raw_data[updated_month],flt_month,tbl_raw_data[analyst_name],flt_analyst,tbl_raw_data[week],E7), IF(flt_analyst="ALL",SUMIFS(tbl_raw_data[time_taken_in_min],tbl_raw_data[updated_month],flt_month,tbl_raw_data[updated_queue],flt_queue,tbl_raw_data[week],E7))))) / IF(AND(flt_queue="ALL",flt_analyst="ALL"),COUNTIFS(tbl_raw_data[updated_month],flt_month,tbl_raw_data[week],E7), IF(AND(flt_queue<>"ALL",flt_analyst<>"ALL"),COUNTIFS(tbl_raw_data[updated_month],flt_month,tbl_raw_data[updated_queue],flt_queue,tbl_raw_data[analyst_name],flt_analyst,tbl_raw_data[week],E7), IF(flt_queue="ALL",COUNTIFS(tbl_raw_data[updated_month],flt_month,tbl_raw_data[analyst_name],flt_analyst,tbl_raw_data[week],E7), IF(flt_analyst="ALL",COUNTIFS(tbl_raw_data[updated_month],flt_month,tbl_raw_data[updated_queue],flt_queue,tbl_raw_data[week],E7))))),"-") -> 19.627299 | F12: =IFERROR(IF(AND(flt_queue="ALL",flt_analyst="ALL"),SUMIFS(tbl_raw_data[time_taken_in_min],tbl_raw_data[updated_month],flt_month,tbl_raw_data[week],F7), IF(AND(flt_queue<>"ALL",flt_analyst<>"ALL"),SUMIFS(tbl_raw_data[time_taken_in_min],tbl_raw_data[updated_month],flt_month,tbl_raw_data[updated_queue],flt_queue,tbl_raw_data[analyst_name],flt_analyst,tbl_raw_data[week],F7), IF(flt_queue="ALL",SUMIFS(tbl_raw_data[time_taken_in_min],tbl_raw_data[updated_month],flt_month,tbl_raw_data[analyst_name],flt_analyst,tbl_raw_data[week],F7), IF(flt_analyst="ALL",SUMIFS(tbl_raw_data[time_taken_in_min],tbl_raw_data[updated_month],flt_month,tbl_raw_data[updated_queue],flt_queue,tbl_raw_data[week],F7))))) / IF(AND(flt_queue="ALL",flt_analyst="ALL"),COUNTIFS(tbl_raw_data[updated_month],flt_month,tbl_raw_data[week],F7), IF(AND(flt_queue<>"ALL",flt_analyst<>"ALL"),COUNTIFS(tbl_raw_data[updated_month],flt_month,tbl_raw_data[updated_queue],flt_queue,tbl_raw_data[analyst_name],flt_analyst,tbl_raw_data[week],F7), IF(flt_queue="ALL",COUNTIFS(tbl_raw_data[updated_month],flt_month,tbl_raw_data[analyst_name],flt_analyst,tbl_raw_data[week],F7), IF(flt_analyst="ALL",COUNTIFS(tbl_raw_data[updated_month],flt_month,tbl_raw_data[updated_queue],flt_queue,tbl_raw_data[week],F7))))),"-") -> 22.687844 | G12: =IFERROR(IF(AND(flt_queue="ALL",flt_analyst="ALL"),SUMIFS(tbl_raw_data[time_taken_in_min],tbl_raw_data[updated_month],flt_month,tbl_raw_data[week],G7), IF(AND(flt_queue<>"ALL",flt_analyst<>"ALL"),SUMIFS(tbl_raw_data[time_taken_in_min],tbl_raw_data[updated_month],flt_month,tbl_raw_data[updated_queue],flt_queue,tbl_raw_data[analyst_name],flt_analyst,tbl_raw_data[week],G7), IF(flt_queue="ALL",SUMIFS(tbl_raw_data[time_taken_in_min],tbl_raw_data[updated_month],flt_month,tbl_raw_data[analyst_name],flt_analyst,tbl_raw_data[week],G7), IF(flt_analyst="ALL",SUMIFS(tbl_raw_data[time_taken_in_min],tbl_raw_data[updated_month],flt_month,tbl_raw_data[updated_queue],flt_queue,tbl_raw_data[week],G7))))) / IF(AND(flt_queue="ALL",flt_analyst="ALL"),COUNTIFS(tbl_raw_data[updated_month],flt_month,tbl_raw_data[week],G7), IF(AND(flt_queue<>"ALL",flt_analyst<>"ALL"),COUNTIFS(tbl_raw_data[updated_month],flt_month,tbl_raw_data[updated_queue],flt_queue,tbl_raw_data[analyst_name],flt_analyst,tbl_raw_data[week],G7), IF(flt_queue="ALL",COUNTIFS(tbl_raw_data[updated_month],flt_month,tbl_raw_data[analyst_name],flt_analyst,tbl_raw_data[week],G7), IF(flt_analyst="ALL",COUNTIFS(tbl_raw_data[updated_month],flt_month,tbl_raw_data[updated_queue],flt_queue,tbl_raw_data[week],G7))))),"-") -> 25.036183 | H12: =IFERROR(IF(AND(flt_queue="ALL",flt_analyst="ALL"),SUMIFS(tbl_raw_data[time_taken_in_min],tbl_raw_data[updated_month],flt_month,tbl_raw_data[week],H7), IF(AND(flt_queue<>"ALL",flt_analyst<>"ALL"),SUMIFS(tbl_raw_data[time_taken_in_min],tbl_raw_data[updated_month],flt_month,tbl_raw_data[updated_queue],flt_queue,tbl_raw_data[analyst_name],flt_analyst,tbl_raw_data[week],H7), IF(flt_queue="ALL",SUMIFS(tbl_raw_data[time_taken_in_min],tbl_raw_data[updated_month],flt_month,tbl_raw_data[analyst_name],flt_analyst,tbl_raw_data[week],H7), IF(flt_analyst="ALL",SUMIFS(tbl_raw_data[time_taken_in_min],tbl_raw_data[updated_month],flt_month,tbl_raw_data[updated_queue],flt_queue,tbl_raw_data[week],H7))))) / IF(AND(flt_queue="ALL",flt_analyst="ALL"),COUNTIFS(tbl_raw_data[updated_month],flt_month,tbl_raw_data[week],H7), IF(AND(flt_queue<>"ALL",flt_analyst<>"ALL"),COUNTIFS(tbl_raw_data[updated_month],flt_month,tbl_raw_data[updated_queue],flt_queue,tbl_raw_data[analyst_name],flt_analyst,tbl_raw_data[week],H7), IF(flt_queue="ALL",COUNTIFS(tbl_raw_data[updated_month],flt_month,tbl_raw_data[analyst_name],flt_analyst,tbl_raw_data[week],H7), IF(flt_analyst="ALL",COUNTIFS(tbl_raw_data[updated_month],flt_month,tbl_raw_data[updated_queue],flt_queue,tbl_raw_data[week],H7))))),"-") -> 19.166051 | I12: R: >25 A: 20-25 G: <20 | S12: Reason Unknown | T12: =IF(AND(flt_queue="ALL",flt_analyst="ALL"),COUNTIFS(tbl_raw_data[updated_month],flt_month,tbl_raw_data[updated_message],S12,tbl_raw_data[updated_outcome],"WITHDRAW"), IF(AND(flt_queue<>"ALL",flt_analyst<>"ALL"),COUNTIFS(tbl_raw_data[updated_month],flt_month,tbl_raw_data[updated_queue],flt_queue,tbl_raw_data[analyst_name],flt_analyst,tbl_raw_data[updated_message],S12,tbl_raw_data[updated_outcome],"WITHDRAW"), IF(flt_queue="ALL",COUNTIFS(tbl_raw_data[updated_month],flt_month,tbl_raw_data[analyst_name],flt_analyst,tbl_raw_data[updated_message],S12,tbl_raw_data[updated_outcome],"WITHDRAW"), IF(flt_analyst="ALL",COUNTIFS(tbl_raw_data[updated_month],flt_month,tbl_raw_data[updated_queue],flt_queue,tbl_raw_data[updated_message],S12,tbl_raw_data[updated_outcome],"WITHDRAW"))))) -> 373 | U12: =T12/$T$13 -> 0.23283396
B13: KPI_6 | C13: # of Applications Handled | D13: =IF(OR(E13=0,F13=0),"-",IF(E13>F13,settings!J3,IF(E13<F13,settings!J2,IF(E13=F13,settings!J4)))) -> ↑ | E13: =IF(AND(flt_queue="ALL",flt_analyst="ALL"),COUNTIFS(tbl_raw_data[updated_month],flt_month,tbl_raw_data[week],E7), IF(AND(flt_queue<>"ALL",flt_analyst<>"ALL"),COUNTIFS(tbl_raw_data[updated_month],flt_month,tbl_raw_data[updated_queue],flt_queue,tbl_raw_data[analyst_name],flt_analyst,tbl_raw_data[week],E7), IF(flt_queue="ALL",COUNTIFS(tbl_raw_data[updated_month],flt_month,tbl_raw_data[analyst_name],flt_analyst,tbl_raw_data[week],E7), IF(flt_analyst="ALL",COUNTIFS(tbl_raw_data[updated_month],flt_month,tbl_raw_data[updated_queue],flt_queue,tbl_raw_data[week],E7))))) -> 1682 | F13: =IF(AND(flt_queue="ALL",flt_analyst="ALL"),COUNTIFS(tbl_raw_data[updated_month],flt_month,tbl_raw_data[week],F7), IF(AND(flt_queue<>"ALL",flt_analyst<>"ALL"),COUNTIFS(tbl_raw_data[updated_month],flt_month,tbl_raw_data[updated_queue],flt_queue,tbl_raw_data[analyst_name],flt_analyst,tbl_raw_data[week],F7), IF(flt_queue="ALL",COUNTIFS(tbl_raw_data[updated_month],flt_month,tbl_raw_data[analyst_name],flt_analyst,tbl_raw_data[week],F7), IF(flt_analyst="ALL",COUNTIFS(tbl_raw_data[updated_month],flt_month,tbl_raw_data[updated_queue],flt_queue,tbl_raw_data[week],F7))))) -> 1297 | G13: =IF(AND(flt_queue="ALL",flt_analyst="ALL"),COUNTIFS(tbl_raw_data[updated_month],flt_month,tbl_raw_data[week],G7), IF(AND(flt_queue<>"ALL",flt_analyst<>"ALL"),COUNTIFS(tbl_raw_data[updated_month],flt_month,tbl_raw_data[updated_queue],flt_queue,tbl_raw_data[analyst_name],flt_analyst,tbl_raw_data[week],G7), IF(flt_queue="ALL",COUNTIFS(tbl_raw_data[updated_month],flt_month,tbl_raw_data[analyst_name],flt_analyst,tbl_raw_data[week],G7), IF(flt_analyst="ALL",COUNTIFS(tbl_raw_data[updated_month],flt_month,tbl_raw_data[updated_queue],flt_queue,tbl_raw_data[week],G7))))) -> 1275 | H13: =IF(AND(flt_queue="ALL",flt_analyst="ALL"),COUNTIFS(tbl_raw_data[updated_month],flt_month,tbl_raw_data[week],H7), IF(AND(flt_queue<>"ALL",flt_analyst<>"ALL"),COUNTIFS(tbl_raw_data[updated_month],flt_month,tbl_raw_data[updated_queue],flt_queue,tbl_raw_data[analyst_name],flt_analyst,tbl_raw_data[week],H7), IF(flt_queue="ALL",COUNTIFS(tbl_raw_data[updated_month],flt_month,tbl_raw_data[analyst_name],flt_analyst,tbl_raw_data[week],H7), IF(flt_analyst="ALL",COUNTIFS(tbl_raw_data[updated_month],flt_month,tbl_raw_data[updated_queue],flt_queue,tbl_raw_data[week],H7))))) -> 1326 | I13: See Notes (1) | K13: =IF(AND(flt_queue="ALL",flt_analyst="ALL"),COUNTIFS(tbl_raw_data[updated_month],flt_month), IF(AND(flt_queue<>"ALL",flt_analyst<>"ALL"),COUNTIFS(tbl_raw_data[updated_month],flt_month,tbl_raw_data[updated_queue],flt_queue,tbl_raw_data[analyst_name],flt_analyst), IF(flt_queue="ALL",COUNTIFS(tbl_raw_data[updated_month],flt_month,tbl_raw_data[analyst_name],flt_analyst), IF(flt_analyst="ALL",COUNTIFS(tbl_raw_data[updated_month],flt_month,tbl_raw_data[updated_queue],flt_queue))))) -> 5580 | S13: Total | T13: =SUM(T7:T12) -> 1602
S16: Notes:
S17: (1) Thresholds are Not Applicable as they can be different at the Team Level & Analyst Level. Data bars are added to help compare the values between weeks. The higher the value, the longer the bar.
S18: (2) Top 40 (by Rank) Reasons are marked in Light Red Background with Red Font.
S19: (3) Applications Data is available for analysis only from 29th July.

Sheet raw_data
A1: Application_ID | B1: Date Tagged | C1: Date Actioned | D1: Outcome | E1: Queue Name | F1: Analyst | G1: Message | H1: updated_message | I1: time_taken | J1: time_taken_in_min | K1: updated_date | L1: updated_month | M1: week | N1: analyst_name | O1: updated_outcome | P1: updated_queue | Q1: sla_met_not_met
A2: 1 | B2: 45137.004 | C2: 45137.392 | D2: Approve | E2: Consumer Post Bureau | F2: QMascarenhas | H2: =IF(OR(ISNUMBER(SEARCH("duplicate",G2)), ISNUMBER(SEARCH("previously",G2)), ISNUMBER(SEARCH("previously approved",G2))), "Duplicate Application", IF(OR(ISNUMBER(SEARCH("incorrect",G2)), ISNUMBER(SEARCH("remove", G2))), "Incorrect Details", IF(ISNUMBER(SEARCH("incomplete",G2)), "Incomplete Details", IF(ISNUMBER(SEARCH("overdue",G2)), "Overdue Bill", IF(OR(ISNUMBER(SEARCH("resubmit as", G2)), ISNUMBER(SEARCH("re-submit as", G2))), "Incorrect Queue", IF(OR(ISNUMBER(SEARCH("100",G2)), ISNUMBER(SEARCH("correct", G2)), ISNUMBER(SEARCH("email", G2)), ISNUMBER(SEARCH("please submit", G2)), ISNUMBER(SEARCH("please resubmit",G2)), ISNUMBER(SEARCH("please re-submit", G2)), ISNUMBER(SEARCH("please send", G2))), "Incomplete Details", IF(ISNUMBER(SEARCH("error", G2)), "System Error", "Reason Unknown"))))))) -> Reason Unknown | I2: =(tbl_raw_data[[#This Row],[Date Actioned]])-(tbl_raw_data[[#This Row],[Date Tagged]]) -> 0.388125 | J2: =HOUR(tbl_raw_data[[#This Row],[time_taken]])*60+MINUTE(tbl_raw_data[[#This Row],[time_taken]])+SECOND(tbl_raw_data[[#This Row],[time_taken]])/60 -> 558.9 | K2: =DATE(YEAR(tbl_raw_data[[#This Row],[Date Actioned]]),MONTH(tbl_raw_data[[#This Row],[Date Actioned]]),DAY(tbl_raw_data[[#This Row],[Date Actioned]])) -> 45137 | L2: =UPPER(TEXT(tbl_raw_data[[#This Row],[updated_date]],"MMMM")) -> JULY | M2: ="WEEK "&IF(ROUNDUP(DAY(tbl_raw_data[[#This Row],[updated_date]])/7,0)=5,4,ROUNDUP(DAY(tbl_raw_data[[#This Row],[updated_date]])/7,0)) -> WEEK 4 | N2: =UPPER(VLOOKUP(tbl_raw_data[[#This Row],[Analyst]],settings!$A$1:$B$15,2,0)) -> QUADIR | O2: =TRIM(UPPER(tbl_raw_data[[#This Row],[Outcome]])) -> APPROVE | P2: =TRIM(UPPER(tbl_raw_data[[#This Row],[Queue Name]])) -> CONSUMER POST BUREAU | Q2: =IF(tbl_raw_data[[#This Row],[time_taken_in_min]]<=settings!$D$2,"SLA_MET","SLA_NOT_MET") -> SLA_NOT_MET
A3: 2 | B3: 45137.387 | C3: 45137.397 | D3: APPROVE | E3: Consumer Existing | F3: NBhatia | G3: Conditionally Approved, if the Customer goes on Direct Debit mode of Payment and pays off the outstanding balance due for $129.29 | H3: =IF(OR(ISNUMBER(SEARCH("duplicate",G3)), ISNUMBER(SEARCH("previously",G3)), ISNUMBER(SEARCH("previously approved",G3))), "Duplicate Application", IF(OR(ISNUMBER(SEARCH("incorrect",G3)), ISNUMBER(SEARCH("remove", G3))), "Incorrect Details", IF(ISNUMBER(SEARCH("incomplete",G3)), "Incomplete Details", IF(ISNUMBER(SEARCH("overdue",G3)), "Overdue Bill", IF(OR(ISNUMBER(SEARCH("resubmit as", G3)), ISNUMBER(SEARCH("re-submit as", G3))), "Incorrect Queue", IF(OR(ISNUMBER(SEARCH("100",G3)), ISNUMBER(SEARCH("correct", G3)), ISNUMBER(SEARCH("email", G3)), ISNUMBER(SEARCH("please submit", G3)), ISNUMBER(SEARCH("please resubmit",G3)), ISNUMBER(SEARCH("please re-submit", G3)), ISNUMBER(SEARCH("please send", G3))), "Incomplete Details", IF(ISNUMBER(SEARCH("error", G3)), "System Error", "Reason Unknown"))))))) -> Reason Unknown | I3: =(tbl_raw_data[[#This Row],[Date Actioned]])-(tbl_raw_data[[#This Row],[Date Tagged]]) -> 0.010150463 | J3: =HOUR(tbl_raw_data[[#This Row],[time_taken]])*60+MINUTE(tbl_raw_data[[#This Row],[time_taken]])+SECOND(tbl_raw_data[[#This Row],[time_taken]])/60 -> 14.616667 | K3: =DATE(YEAR(tbl_raw_data[[#This Row],[Date Actioned]]),MONTH(tbl_raw_data[[#This Row],[Date Actioned]]),DAY(tbl_raw_data[[#This Row],[Date Actioned]])) -> 45137 | L3: =UPPER(TEXT(tbl_raw_data[[#This Row],[updated_date]],"MMMM")) -> JULY | M3: ="WEEK "&IF(ROUNDUP(DAY(tbl_raw_data[[#This Row],[updated_date]])/7,0)=5,4,ROUNDUP(DAY(tbl_raw_data[[#This Row],[updated_date]])/7,0)) -> WEEK 4 | N3: =UPPER(VLOOKUP(tbl_raw_data[[#This Row],[Analyst]],settings!$A$1:$B$15,2,0)) -> NITESH | O3: =TRIM(UPPER(tbl_raw_data[[#This Row],[Outcome]])) -> APPROVE | P3: =TRIM(UPPER(tbl_raw_data[[#This Row],[Queue Name]])) -> CONSUMER EXISTING | Q3: =IF(tbl_raw_data[[#This Row],[time_taken_in_min]]<=settings!$D$2,"SLA_MET","SLA_NOT_MET") -> SLA_MET
A4: 3 | B4: 45137.395 | C4: 45137.407 | D4: APPROVE | E4: Consumer Existing | F4: CDcosta | G4: Approve | H4: =IF(OR(ISNUMBER(SEARCH("duplicate",G4)), ISNUMBER(SEARCH("previously",G4)), ISNUMBER(SEARCH("previously approved",G4))), "Duplicate Application", IF(OR(ISNUMBER(SEARCH("incorrect",G4)), ISNUMBER(SEARCH("remove", G4))), "Incorrect Details", IF(ISNUMBER(SEARCH("incomplete",G4)), "Incomplete Details", IF(ISNUMBER(SEARCH("overdue",G4)), "Overdue Bill", IF(OR(ISNUMBER(SEARCH("resubmit as", G4)), ISNUMBER(SEARCH("re-submit as", G4))), "Incorrect Queue", IF(OR(ISNUMBER(SEARCH("100",G4)), ISNUMBER(SEARCH("correct", G4)), ISNUMBER(SEARCH("email", G4)), ISNUMBER(SEARCH("please submit", G4)), ISNUMBER(SEARCH("please resubmit",G4)), ISNUMBER(SEARCH("please re-submit", G4)), ISNUMBER(SEARCH("please send", G4))), "Incomplete Details", IF(ISNUMBER(SEARCH("error", G4)), "System Error", "Reason Unknown"))))))) -> Reason Unknown | I4: =(tbl_raw_data[[#This Row],[Date Actioned]])-(tbl_raw_data[[#This Row],[Date Tagged]]) -> 0.011759259 | J4: =HOUR(tbl_raw_data[[#This Row],[time_taken]])*60+MINUTE(tbl_raw_data[[#This Row],[time_taken]])+SECOND(tbl_raw_data[[#This Row],[time_taken]])/60 -> 16.933333 | K4: =DATE(YEAR(tbl_raw_data[[#This Row],[Date Actioned]]),MONTH(tbl_raw_data[[#This Row],[Date Actioned]]),DAY(tbl_raw_data[[#This Row],[Date Actioned]])) -> 45137 | L4: =UPPER(TEXT(tbl_raw_data[[#This Row],[updated_date]],"MMMM")) -> JULY | M4: ="WEEK "&IF(ROUNDUP(DAY(tbl_raw_data[[#This Row],[updated_date]])/7,0)=5,4,ROUNDUP(DAY(tbl_raw_data[[#This Row],[updated_date]])/7,0)) -> WEEK 4 | N4: =UPPER(VLOOKUP(tbl_raw_data[[#This Row],[Analyst]],settings!$A$1:$B$15,2,0)) -> CAMROON | O4: =TRIM(UPPER(tbl_raw_data[[#This Row],[Outcome]])) -> APPROVE | P4: =TRIM(UPPER(tbl_raw_data[[#This Row],[Queue Name]])) -> CONSUMER EXISTING | Q4: =IF(tbl_raw_data[[#This Row],[time_taken_in_min]]<=settings!$D$2,"SLA_MET","SLA_NOT_MET") -> SLA_MET
A5: 4 | B5: 45137.401 | C5: 45137.409 | D5: Approve | E5: Consumer Existing | F5: QMascarenhas | H5: =IF(OR(ISNUMBER(SEARCH("duplicate",G5)), ISNUMBER(SEARCH("previously",G5)), ISNUMBER(SEARCH("previously approved",G5))), "Duplicate Application", IF(OR(ISNUMBER(SEARCH("incorrect",G5)), ISNUMBER(SEARCH("remove", G5))), "Incorrect Details", IF(ISNUMBER(SEARCH("incomplete",G5)), "Incomplete Details", IF(ISNUMBER(SEARCH("overdue",G5)), "Overdue Bill", IF(OR(ISNUMBER(SEARCH("resubmit as", G5)), ISNUMBER(SEARCH("re-submit as", G5))), "Incorrect Queue", IF(OR(ISNUMBER(SEARCH("100",G5)), ISNUMBER(SEARCH("correct", G5)), ISNUMBER(SEARCH("email", G5)), ISNUMBER(SEARCH("please submit", G5)), ISNUMBER(SEARCH("please resubmit",G5)), ISNUMBER(SEARCH("please re-submit", G5)), ISNUMBER(SEARCH("please send", G5))), "Incomplete Details", IF(ISNUMBER(SEARCH("error", G5)), "System Error", "Reason Unknown"))))))) -> Reason Unknown | I5: =(tbl_raw_data[[#This Row],[Date Actioned]])-(tbl_raw_data[[#This Row],[Date Tagged]]) -> 0.0085532407 | J5: =HOUR(tbl_raw_data[[#This Row],[time_taken]])*60+MINUTE(tbl_raw_data[[#This Row],[time_taken]])+SECOND(tbl_raw_data[[#This Row],[time_taken]])/60 -> 12.316667 | K5: =DATE(YEAR(tbl_raw_data[[#This Row],[Date Actioned]]),MONTH(tbl_raw_data[[#This Row],[Date Actioned]]),DAY(tbl_raw_data[[#This Row],[Date Actioned]])) -> 45137 | L5: =UPPER(TEXT(tbl_raw_data[[#This Row],[updated_date]],"MMMM")) -> JULY | M5: ="WEEK "&IF(ROUNDUP(DAY(tbl_raw_data[[#This Row],[updated_date]])/7,0)=5,4,ROUNDUP(DAY(tbl_raw_data[[#This Row],[updated_date]])/7,0)) -> WEEK 4 | N5: =UPPER(VLOOKUP(tbl_raw_data[[#This Row],[Analyst]],settings!$A$1:$B$15,2,0)) -> QUADIR | O5: =TRIM(UPPER(tbl_raw_data[[#This Row],[Outcome]])) -> APPROVE | P5: =TRIM(UPPER(tbl_raw_data[[#This Row],[Queue Name]])) -> CONSUMER EXISTING | Q5: =IF(tbl_raw_data[[#This Row],[time_taken_in_min]]<=settings!$D$2,"SLA_MET","SLA_NOT_MET") -> SLA_MET
A6: 5 | B6: 45137.403 | C6: 45137.415 | D6: APPROVE | E6: Consumer Existing | F6: CDcosta | G6: Approve | H6: =IF(OR(ISNUMBER(SEARCH("duplicate",G6)), ISNUMBER(SEARCH("previously",G6)), ISNUMBER(SEARCH("previously approved",G6))), "Duplicate Application", IF(OR(ISNUMBER(SEARCH("incorrect",G6)), ISNUMBER(SEARCH("remove", G6))), "Incorrect Details", IF(ISNUMBER(SEARCH("incomplete",G6)), "Incomplete Details", IF(ISNUMBER(SEARCH("overdue",G6)), "Overdue Bill", IF(OR(ISNUMBER(SEARCH("resubmit as", G6)), ISNUMBER(SEARCH("re-submit as", G6))), "Incorrect Queue", IF(OR(ISNUMBER(SEARCH("100",G6)), ISNUMBER(SEARCH("correct", G6)), ISNUMBER(SEARCH("email", G6)), ISNUMBER(SEARCH("please submit", G6)), ISNUMBER(SEARCH("please resubmit",G6)), ISNUMBER(SEARCH("please re-submit", G6)), ISNUMBER(SEARCH("please send", G6))), "Incomplete Details", IF(ISNUMBER(SEARCH("error", G6)), "System Error", "Reason Unknown"))))))) -> Reason Unknown | I6: =(tbl_raw_data[[#This Row],[Date Actioned]])-(tbl_raw_data[[#This Row],[Date Tagged]]) -> 0.011944444 | J6: =HOUR(tbl_raw_data[[#This Row],[time_taken]])*60+MINUTE(tbl_raw_data[[#This Row],[time_taken]])+SECOND(tbl_raw_data[[#This Row],[time_taken]])/60 -> 17.2 | K6: =DATE(YEAR(tbl_raw_data[[#This Row],[Date Actioned]]),MONTH(tbl_raw_data[[#This Row],[Date Actioned]]),DAY(tbl_raw_data[[#This Row],[Date Actioned]])) -> 45137 | L6: =UPPER(TEXT(tbl_raw_data[[#This Row],[updated_date]],"MMMM")) -> JULY | M6: ="WEEK "&IF(ROUNDUP(DAY(tbl_raw_data[[#This Row],[updated_date]])/7,0)=5,4,ROUNDUP(DAY(tbl_raw_data[[#This Row],[updated_date]])/7,0)) -> WEEK 4 | N6: =UPPER(VLOOKUP(tbl_raw_data[[#This Row],[Analyst]],settings!$A$1:$B$15,2,0)) -> CAMROON | O6: =TRIM(UPPER(tbl_raw_data[[#This Row],[Outcome]])) -> APPROVE | P6: =TRIM(UPPER(tbl_raw_data[[#This Row],[Queue Name]])) -> CONSUMER EXISTING | Q6: =IF(tbl_raw_data[[#This Row],[time_taken_in_min]]<=settings!$D$2,"SLA_MET","SLA_NOT_MET") -> SLA_MET
A7: 6 | B7: 45137.406 | C7: 45137.414 | D7: Approve | E7: Consumer Post Bureau | F7: QMascarenhas | H7: =IF(OR(ISNUMBER(SEARCH("duplicate",G7)), ISNUMBER(SEARCH("previously",G7)), ISNUMBER(SEARCH("previously approved",G7))), "Duplicate Application", IF(OR(ISNUMBER(SEARCH("incorrect",G7)), ISNUMBER(SEARCH("remove", G7))), "Incorrect Details", IF(ISNUMBER(SEARCH("incomplete",G7)), "Incomplete Details", IF(ISNUMBER(SEARCH("overdue",G7)), "Overdue Bill", IF(OR(ISNUMBER(SEARCH("resubmit as", G7)), ISNUMBER(SEARCH("re-submit as", G7))), "Incorrect Queue", IF(OR(ISNUMBER(SEARCH("100",G7)), ISNUMBER(SEARCH("correct", G7)), ISNUMBER(SEARCH("email", G7)), ISNUMBER(SEARCH("please submit", G7)), ISNUMBER(SEARCH("please resubmit",G7)), ISNUMBER(SEARCH("please re-submit", G7)), ISNUMBER(SEARCH("please send", G7))), "Incomplete Details", IF(ISNUMBER(SEARCH("error", G7)), "System Error", "Reason Unknown"))))))) -> Reason Unknown | I7: =(tbl_raw_data[[#This Row],[Date Actioned]])-(tbl_raw_data[[#This Row],[Date Tagged]]) -> 0.0082175926 | J7: =HOUR(tbl_raw_data[[#This Row],[time_taken]])*60+MINUTE(tbl_raw_data[[#This Row],[time_taken]])+SECOND(tbl_raw_data[[#This Row],[time_taken]])/60 -> 11.833333 | K7: =DATE(YEAR(tbl_raw_data[[#This Row],[Date Actioned]]),MONTH(tbl_raw_data[[#This Row],[Date Actioned]]),DAY(tbl_raw_data[[#This Row],[Date Actioned]])) -> 45137 | L7: =UPPER(TEXT(tbl_raw_data[[#This Row],[updated_date]],"MMMM")) -> JULY | M7: ="WEEK "&IF(ROUNDUP(DAY(tbl_raw_data[[#This Row],[updated_date]])/7,0)=5,4,ROUNDUP(DAY(tbl_raw_data[[#This Row],[updated_date]])/7,0)) -> WEEK 4 | N7: =UPPER(VLOOKUP(tbl_raw_data[[#This Row],[Analyst]],settings!$A$1:$B$15,2,0)) -> QUADIR | O7: =TRIM(UPPER(tbl_raw_data[[#This Row],[Outcome]])) -> APPROVE | P7: =TRIM(UPPER(tbl_raw_data[[#This Row],[Queue Name]])) -> CONSUMER POST BUREAU | Q7: =IF(tbl_raw_data[[#This Row],[time_taken_in_min]]<=settings!$D$2,"SLA_MET","SLA_NOT_MET") -> SLA_MET
A8: 7 | B8: 45137.419 | C8: 45137.428 | D8: Approve | E8: Consumer Existing | F8: QMascarenhas | H8: =IF(OR(ISNUMBER(SEARCH("duplicate",G8)), ISNUMBER(SEARCH("previously",G8)), ISNUMBER(SEARCH("previously approved",G8))), "Duplicate Application", IF(OR(ISNUMBER(SEARCH("incorrect",G8)), ISNUMBER(SEARCH("remove", G8))), "Incorrect Details", IF(ISNUMBER(SEARCH("incomplete",G8)), "Incomplete Details", IF(ISNUMBER(SEARCH("overdue",G8)), "Overdue Bill", IF(OR(ISNUMBER(SEARCH("resubmit as", G8)), ISNUMBER(SEARCH("re-submit as", G8))), "Incorrect Queue", IF(OR(ISNUMBER(SEARCH("100",G8)), ISNUMBER(SEARCH("correct", G8)), ISNUMBER(SEARCH("email", G8)), ISNUMBER(SEARCH("please submit", G8)), ISNUMBER(SEARCH("please resubmit",G8)), ISNUMBER(SEARCH("please re-submit", G8)), ISNUMBER(SEARCH("please send", G8))), "Incomplete Details", IF(ISNUMBER(SEARCH("error", G8)), "System Error", "Reason Unknown"))))))) -> Reason Unknown | I8: =(tbl_raw_data[[#This Row],[Date Actioned]])-(tbl_raw_data[[#This Row],[Date Tagged]]) -> 0.0092824074 | J8: =HOUR(tbl_raw_data[[#This Row],[time_taken]])*60+MINUTE(tbl_raw_data[[#This Row],[time_taken]])+SECOND(tbl_raw_data[[#This Row],[time_taken]])/60 -> 13.366667 | K8: =DATE(YEAR(tbl_raw_data[[#This Row],[Date Actioned]]),MONTH(tbl_raw_data[[#This Row],[Date Actioned]]),DAY(tbl_raw_data[[#This Row],[Date Actioned]])) -> 45137 | L8: =UPPER(TEXT(tbl_raw_data[[#This Row],[updated_date]],"MMMM")) -> JULY | M8: ="WEEK "&IF(ROUNDUP(DAY(tbl_raw_data[[#This Row],[updated_date]])/7,0)=5,4,ROUNDUP(DAY(tbl_raw_data[[#This Row],[updated_date]])/7,0)) -> WEEK 4 | N8: =UPPER(VLOOKUP(tbl_raw_data[[#This Row],[Analyst]],settings!$A$1:$B$15,2,0)) -> QUADIR | O8: =TRIM(UPPER(tbl_raw_data[[#This Row],[Outcome]])) -> APPROVE | P8: =TRIM(UPPER(tbl_raw_data[[#This Row],[Queue Name]])) -> CONSUMER EXISTING | Q8: =IF(tbl_raw_data[[#This Row],[time_taken_in_min]]<=settings!$D$2,"SLA_MET","SLA_NOT_MET") -> SLA_MET
A9: 8 | B9: 45137.434 | C9: 45137.443 | D9: APPROVE | E9: Consumer Post Bureau | F9: CDcosta | G9: Approved for 1 handset and 1 MBB | H9: =IF(OR(ISNUMBER(SEARCH("duplicate",G9)), ISNUMBER(SEARCH("previously",G9)), ISNUMBER(SEARCH("previously approved",G9))), "Duplicate Application", IF(OR(ISNUMBER(SEARCH("incorrect",G9)), ISNUMBER(SEARCH("remove", G9))), "Incorrect Details", IF(ISNUMBER(SEARCH("incomplete",G9)), "Incomplete Details", IF(ISNUMBER(SEARCH("overdue",G9)), "Overdue Bill", IF(OR(ISNUMBER(SEARCH("resubmit as", G9)), ISNUMBER(SEARCH("re-submit as", G9))), "Incorrect Queue", IF(OR(ISNUMBER(SEARCH("100",G9)), ISNUMBER(SEARCH("correct", G9)), ISNUMBER(SEARCH("email", G9)), ISNUMBER(SEARCH("please submit", G9)), ISNUMBER(SEARCH("please resubmit",G9)), ISNUMBER(SEARCH("please re-submit", G9)), ISNUMBER(SEARCH("please send", G9))), "Incomplete Details", IF(ISNUMBER(SEARCH("error", G9)), "System Error", "Reason Unknown"))))))) -> Reason Unknown | I9: =(tbl_raw_data[[#This Row],[Date Actioned]])-(tbl_raw_data[[#This Row],[Date Tagged]]) -> 0.0090509259 | J9: =HOUR(tbl_raw_data[[#This Row],[time_taken]])*60+MINUTE(tbl_raw_data[[#This Row],[time_taken]])+SECOND(tbl_raw_data[[#This Row],[time_taken]])/60 -> 13.033333 | K9: =DATE(YEAR(tbl_raw_data[[#This Row],[Date Actioned]]),MONTH(tbl_raw_data[[#This Row],[Date Actioned]]),DAY(tbl_raw_data[[#This Row],[Date Actioned]])) -> 45137 | L9: =UPPER(TEXT(tbl_raw_data[[#This Row],[updated_date]],"MMMM")) -> JULY | M9: ="WEEK "&IF(ROUNDUP(DAY(tbl_raw_data[[#This Row],[updated_date]])/7,0)=5,4,ROUNDUP(DAY(tbl_raw_data[[#This Row],[updated_date]])/7,0)) -> WEEK 4 | N9: =UPPER(VLOOKUP(tbl_raw_data[[#This Row],[Analyst]],settings!$A$1:$B$15,2,0)) -> CAMROON | O9: =TRIM(UPPER(tbl_raw_data[[#This Row],[Outcome]])) -> APPROVE | P9: =TRIM(UPPER(tbl_raw_data[[#This Row],[Queue Name]])) -> CONSUMER POST BUREAU | Q9: =IF(tbl_raw_data[[#This Row],[time_taken_in_min]]<=settings!$D$2,"SLA_MET","SLA_NOT_MET") -> SLA_MET
A10: 9 | B10: 45137.437 | C10: 45137.443 | D10: APPROVE | E10: Consumer Existing | F10: MDcruz | G10: Approve | H10: =IF(OR(ISNUMBER(SEARCH("duplicate",G10)), ISNUMBER(SEARCH("previously",G10)), ISNUMBER(SEARCH("previously approved",G10))), "Duplicate Application", IF(OR(ISNUMBER(SEARCH("incorrect",G10)), ISNUMBER(SEARCH("remove", G10))), "Incorrect Details", IF(ISNUMBER(SEARCH("incomplete",G10)), "Incomplete Details", IF(ISNUMBER(SEARCH("overdue",G10)), "Overdue Bill", IF(OR(ISNUMBER(SEARCH("resubmit as", G10)), ISNUMBER(SEARCH("re-submit as", G10))), "Incorrect Queue", IF(OR(ISNUMBER(SEARCH("100",G10)), ISNUMBER(SEARCH("correct", G10)), ISNUMBER(SEARCH("email", G10)), ISNUMBER(SEARCH("please submit", G10)), ISNUMBER(SEARCH("please resubmit",G10)), ISNUMBER(SEARCH("please re-submit", G10)), ISNUMBER(SEARCH("please send", G10))), "Incomplete Details", IF(ISNUMBER(SEARCH("error", G10)), "System Error", "Reason Unknown"))))))) -> Reason Unknown | I10: =(tbl_raw_data[[#This Row],[Date Actioned]])-(tbl_raw_data[[#This Row],[Date Tagged]]) -> 0.0063657407 | J10: =HOUR(tbl_raw_data[[#This Row],[time_taken]])*60+MINUTE(tbl_raw_data[[#This Row],[time_taken]])+SECOND(tbl_raw_data[[#This Row],[time_taken]])/60 -> 9.1666667 | K10: =DATE(YEAR(tbl_raw_data[[#This Row],[Date Actioned]]),MONTH(tbl_raw_data[[#This Row],[Date Actioned]]),DAY(tbl_raw_data[[#This Row],[Date Actioned]])) -> 45137 | L10: =UPPER(TEXT(tbl_raw_data[[#This Row],[updated_date]],"MMMM")) -> JULY | M10: ="WEEK "&IF(ROUNDUP(DAY(tbl_raw_data[[#This Row],[updated_date]])/7,0)=5,4,ROUNDUP(DAY(tbl_raw_data[[#This Row],[updated_date]])/7,0)) -> WEEK 4 | N10: =UPPER(VLOOKUP(tbl_raw_data[[#This Row],[Analyst]],settings!$A$1:$B$15,2,0)) -> MERCEDES | O10: =TRIM(UPPER(tbl_raw_data[[#This Row],[Outcome]])) -> APPROVE | P10: =TRIM(UPPER(tbl_raw_data[[#This Row],[Queue Name]])) -> CONSUMER EXISTING | Q10: =IF(tbl_raw_data[[#This Row],[time_taken_in_min]]<=settings!$D$2,"SLA_MET","SLA_NOT_MET") -> SLA_MET
